Starting MCP server with command: /Users/miles/Documents/JiangNing/django-erp-os-framework/.venv/bin/python /Users/miles/Documents/JiangNing/django-erp-os-framework/src/manage.py run_mcp_server
Working directory: /Users/miles/Documents/JiangNing/django-erp-os-framework/src
Manage.py path: /Users/miles/Documents/JiangNing/django-erp-os-framework/src/manage.py
--------------------------------------------------
2025-05-24 22:25:45,937 DEBUG Using selector: KqueueSelector
System check identified some issues:

WARNINGS:
?: (urls.W005) URL namespace 'ApplicationsSite' isn't unique. You may not be able to reverse all URLs in this namespace
Starting MCP Server...
2025-05-24 22:25:46,470 DEBUG Initializing server 'ERPSysDataItemMCP'
2025-05-24 22:25:46,470 DEBUG Registering handler for ListToolsRequest
2025-05-24 22:25:46,470 DEBUG Registering handler for CallToolRequest
2025-05-24 22:25:46,470 DEBUG Registering handler for ListResourcesRequest
2025-05-24 22:25:46,470 DEBUG Registering handler for ReadResourceRequest
2025-05-24 22:25:46,470 DEBUG Registering handler for PromptListRequest
2025-05-24 22:25:46,470 DEBUG Registering handler for GetPromptRequest
2025-05-24 22:25:46,470 DEBUG Registering handler for ListResourceTemplatesRequest
Running MCP Server with stdio transport...
[05/24/25 22:25:46] INFO     Starting server "ERPSysDataItemMCP"...                                                                                                    server.py:214
2025-05-24 22:25:46,476 INFO Starting server "ERPSysDataItemMCP"...
2025-05-24 22:25:46,480 DEBUG Using selector: KqueueSelector
MCP Server failed to start: unhandled errors in a TaskGroup (1 sub-exception)
  + Exception Group Traceback (most recent call last):
  |   File "/Users/miles/Documents/JiangNing/django-erp-os-framework/src/mcp_servers/management/commands/run_mcp_server.py", line 28, in handle
  |     mcp.run()
  |   File "/Users/miles/Documents/JiangNing/django-erp-os-framework/.venv/lib/python3.12/site-packages/fastmcp/server/server.py", line 216, in run
  |     anyio.run(partial(self.run_async, transport, **transport_kwargs))
  |   File "/Users/miles/Documents/JiangNing/django-erp-os-framework/.venv/lib/python3.12/site-packages/anyio/_core/_eventloop.py", line 74, in run
  |     return async_backend.run(func, args, {}, backend_options)
  |            ^^^^^^^^^^^^^^^^^^^^^^^^^^^^^^^^^^^^^^^^^^^^^^^^^^
  |   File "/Users/miles/Documents/JiangNing/django-erp-os-framework/.venv/lib/python3.12/site-packages/anyio/_backends/_asyncio.py", line 2310, in run
  |     return runner.run(wrapper())
  |            ^^^^^^^^^^^^^^^^^^^^^
  |   File "/Users/miles/.pyenv/versions/3.12.1/lib/python3.12/asyncio/runners.py", line 118, in run
  |     return self._loop.run_until_complete(task)
  |            ^^^^^^^^^^^^^^^^^^^^^^^^^^^^^^^^^^^
  |   File "/Users/miles/.pyenv/versions/3.12.1/lib/python3.12/asyncio/base_events.py", line 684, in run_until_complete
  |     return future.result()
  |            ^^^^^^^^^^^^^^^
  |   File "/Users/miles/Documents/JiangNing/django-erp-os-framework/.venv/lib/python3.12/site-packages/anyio/_backends/_asyncio.py", line 2298, in wrapper
  |     return await func(*args)
  |            ^^^^^^^^^^^^^^^^^
  |   File "/Users/miles/Documents/JiangNing/django-erp-os-framework/.venv/lib/python3.12/site-packages/fastmcp/server/server.py", line 196, in run_async
  |     await self.run_stdio_async(**transport_kwargs)
  |   File "/Users/miles/Documents/JiangNing/django-erp-os-framework/.venv/lib/python3.12/site-packages/fastmcp/server/server.py", line 730, in run_stdio_async
  |     async with stdio_server() as (read_stream, write_stream):
  |   File "/Users/miles/.pyenv/versions/3.12.1/lib/python3.12/contextlib.py", line 217, in __aexit__
  |     await anext(self.gen)
  |   File "/Users/miles/Documents/JiangNing/django-erp-os-framework/.venv/lib/python3.12/site-packages/mcp/server/stdio.py", line 87, in stdio_server
  |     async with anyio.create_task_group() as tg:
  |   File "/Users/miles/Documents/JiangNing/django-erp-os-framework/.venv/lib/python3.12/site-packages/anyio/_backends/_asyncio.py", line 772, in __aexit__
  |     raise BaseExceptionGroup(
  | ExceptionGroup: unhandled errors in a TaskGroup (1 sub-exception)
  +-+---------------- 1 ----------------
    | Traceback (most recent call last):
    |   File "/Users/miles/Documents/JiangNing/django-erp-os-framework/.venv/lib/python3.12/site-packages/mcp/server/stdio.py", line 63, in stdin_reader
    |     async for line in stdin:
    |   File "/Users/miles/Documents/JiangNing/django-erp-os-framework/.venv/lib/python3.12/site-packages/anyio/_core/_fileio.py", line 83, in __aiter__
    |     line = await self.readline()
    |            ^^^^^^^^^^^^^^^^^^^^^
    |   File "/Users/miles/Documents/JiangNing/django-erp-os-framework/.venv/lib/python3.12/site-packages/anyio/_core/_fileio.py", line 99, in readline
    |     return await to_thread.run_sync(self._fp.readline)
    |            ^^^^^^^^^^^^^^^^^^^^^^^^^^^^^^^^^^^^^^^^^^^
    |   File "/Users/miles/Documents/JiangNing/django-erp-os-framework/.venv/lib/python3.12/site-packages/anyio/to_thread.py", line 56, in run_sync
    |     return await get_async_backend().run_sync_in_worker_thread(
    |            ^^^^^^^^^^^^^^^^^^^^^^^^^^^^^^^^^^^^^^^^^^^^^^^^^^^^
    |   File "/Users/miles/Documents/JiangNing/django-erp-os-framework/.venv/lib/python3.12/site-packages/anyio/_backends/_asyncio.py", line 2470, in run_sync_in_worker_thread
    |     return await future
    |            ^^^^^^^^^^^^
    |   File "/Users/miles/Documents/JiangNing/django-erp-os-framework/.venv/lib/python3.12/site-packages/anyio/_backends/_asyncio.py", line 967, in run
    |     result = context.run(func, *args)
    |              ^^^^^^^^^^^^^^^^^^^^^^^^
    | OSError: [Errno 5] Input/output error
    +------------------------------------
